Workbook
Name ABGLE: #REF!
Name ABGLE: #REF!
Name ABGLE: #REF!
Name ABGLE: #REF!
Name ABGLE: #REF!
Name ABGLE: #REF!
Name ABGLE: #REF!
Name ABGLE: #REF!
Name ABGLE: #REF!
Name ABGLE: #REF!
Name AI: #REF!
Name AI: #REF!
Name AI: #REF!
Name AI: #REF!
Name AI: #REF!
Name AI: #REF!
Name AI: #REF!
Name AI: #REF!
Name ANGLE: '01_1.35 KL'!$D$12
Name ANGLE: '02 & 04_0.02 KL'!$D$12
Name ANGLE: '03_0.330 KL'!$D$12
Name ANGLE: '05_0.942 KL'!$D$12
Name ANGLE: '06_0.330 KL'!$D$12
Name ANGLE: #REF!
Name ANGLE: #REF!
Name ANGLE: '[1]1_5 KL PP FRP TANK'!$C$9
Name ANGLE: '[1]1_5 KL PP FRP TANK'!$C$9
Name ANGLE: #REF!
Name ANGLE2: #REF!
Name ANGLE2: #REF!
Name ANGLE2: #REF!
Name ANGLE2: #REF!
Name ANGLE2: #REF!
Name ANGLE2: #REF!
Name ANGLE2: '[2]PCS WITH INBUILT TANK'!$E$15
Name ANGLE2: #REF!
Name ANGLE2: #REF!
Name ANGLE2: #REF!
Name AREA: '01_1.35 KL'!$U$40:$U$57
Name AREA: '02 & 04_0.02 KL'!$U$40:$U$57
Name AREA: '03_0.330 KL'!$U$40:$U$57
Name AREA: '05_0.942 KL'!$U$40:$U$57
Name AREA: '06_0.330 KL'!$U$40:$U$57
Name AREA: #REF!
Name AREA: #REF!
Name AREA: #REF!
Name AREA: #REF!
Name AREA: #REF!
Name AREA1: '01_1.35 KL'!$U$39:$U$57
Name AREA1: '02 & 04_0.02 KL'!$U$39:$U$57
Name AREA1: '03_0.330 KL'!$U$39:$U$57
Name AREA1: '05_0.942 KL'!$U$39:$U$57
Name AREA1: '06_0.330 KL'!$U$39:$U$57
Name AREA1: #REF!
Name AREA1: #REF!
Name AREA1: #REF!
Name AREA1: #REF!
Name AREA1: #REF!
Name B.ANGLE: '01_1.35 KL'!#REF!
Name B.ANGLE: '02 & 04_0.02 KL'!#REF!

Sheet SUMMARY
N2: 44554 | O2: R1
A3: SUMMARY | N3: 44551 | O3: R1
N4: DATE : 01.11.2021
J5: OFFERED _ 21.12.2021 | M5: DISCOUNTED 11 % _ 24.12.2021
A6: SR. NO. | B6: IITEM | C6: CAP. | D6: SIZE | E6: QTY | F6: MOC | G6: FLUID | H6: UNIT COST W/O LABOUR | I6: TOTAL COST W/O LABOUR | J6: UNIT SALE | K6: TOTAL SALE | L6: FACT. | M6: UNIT SALE | N6: TOTAL SALE | O6: FACT.
A7: 1 | B7: ACID MEASURING TANK (SAC) | C7: 1.35 KL | D7: 1200 ID X 1200 LG. | E7: 2 | F7: FRP (BISPHENOL) | G7: 30 % HCL | H7: ='01_1.35 KL'!G138 -> 90489.2 | I7: =H7*E7 -> 180978.4 | J7: ='01_1.35 KL'!I142 -> 203000 | K7: =J7*E7 -> 406000 | L7: =H7/J7 -> 0.44575961 | M7: =CEILING(J7*0.89,500) -> 181000 | N7: =M7*E7 -> 362000 | O7: =H7/M7 -> 0.49994033
A8: 2 | B8: FUME ABSORBER (SAC) | C8: 0.021 KL | D8: 300 ID X 300 LG. | E8: 2 | F8: FRP (BISPHENOL) | G8: 30 % HCL | H8: ='02 & 04_0.02 KL'!G138 -> 17430.113 | I8: =H8*E8 -> 34860.226 | J8: ='02 & 04_0.02 KL'!I142 -> 46500 | K8: =J8*E8 -> 93000 | L8: =H8/J8 -> 0.37484114 | M8: =CEILING(J8*0.89,500) -> 41500 | N8: =M8*E8 -> 83000 | O8: =H8/M8 -> 0.42000272
A9: 3 | B9: ACID MEASURING TANK (MB) | C9: 0.330 KL | D9: 600 ID X 1200 LG. | E9: 2 | F9: FRP (BISPHENOL) | G9: 30 % HCL | H9: ='03_0.330 KL'!G138 -> 44924.7 | I9: =H9*E9 -> 89849.4 | J9: ='03_0.330 KL'!I142 -> 107000 | K9: =J9*E9 -> 214000 | L9: =H9/J9 -> 0.41985701 | M9: =CEILING(J9*0.89,500) -> 95500 | N9: =M9*E9 -> 191000 | O9: =H9/M9 -> 0.47041571
A10: 4 | B10: FUME ABSORBER (MB) | C10: 0.021 KL | D10: 300 ID X 300 LG. | E10: 2 | F10: FRP (BISPHENOL) | G10: 30 % HCL | H10: ='02 & 04_0.02 KL'!G138 -> 17430.113 | I10: =H10*E10 -> 34860.226 | J10: ='02 & 04_0.02 KL'!I142 -> 46500 | K10: =J10*E10 -> 93000 | L10: =H10/J10 -> 0.37484114 | M10: =CEILING(J10*0.89,500) -> 41500 | N10: =M10*E10 -> 83000 | O10: =H10/M10 -> 0.42000272
A11: 5 | B11: ALKALI MEASURING TANK (SBA) | C11: 0.942 KL | D11: 1000 ID X 1200 LG. | E11: 2 | F11: FRP (BISPHENOL) | G11: 30 % NAOH | H11: ='05_0.942 KL'!G139 -> 78564.368 | I11: =H11*E11 -> 157128.74 | J11: ='05_0.942 KL'!I143 -> 186000 | K11: =J11*E11 -> 372000 | L11: =H11/J11 -> 0.42238908 | M11: =CEILING(J11*0.89,500) -> 166000 | N11: =M11*E11 -> 332000 | O11: =H11/M11 -> 0.47327933
A12: 6 | B12: ALKALI MEASURING / DILUTION TANK (MB) | C12: 0.340 KL | D12: 600 ID X 1200 LG. | E12: 2 | F12: FRP (BISPHENOL) | G12: 30 % NAOH | H12: ='06_0.330 KL'!G139 -> 50982.009 | I12: =H12*E12 -> 101964.02 | J12: ='06_0.330 KL'!I143 -> 121000 | K12: =J12*E12 -> 242000 | L12: =H12/J12 -> 0.42133892 | M12: =CEILING(J12*0.89,500) -> 108000 | N12: =M12*E12 -> 216000 | O12: =H12/M12 -> 0.47205564
I13: =SUM(I7:I12) -> 599641.01 | K13: =SUM(K7:K12) -> 1420000 | L13: =I13/K13 -> 0.4222824 | N13: =SUM(N7:N12) -> 1267000 | O13: =I13/N13 -> 0.47327625
I15: IF 10 % DISC GIVEN THEN | K15: =CEILING(K13*0.9,500) -> 1278000 | L15: =I13/K15 -> 0.46920267
B16: DESCRIPTION | D16: QTY | E16: UOM | F16: RATE (Rs.)
B17: ISOPHTHALIC | D17: =CEILING((E7*'01_1.35 KL'!D124)+(E8*'02 & 04_0.02 KL'!D124)+(SUMMARY!E9*'03_0.330 KL'!D124)+(SUMMARY!E10*'02 & 04_0.02 KL'!D124)+(SUMMARY!E11*'05_0.942 KL'!D125)+(SUMMARY!E12*'06_0.330 KL'!D125),10) -> 1000 | E17: KG | F17: ='RESIN RATE'!D6 -> 325 | I17: TOTAL TRANSPORT COST | J17: F.O.R. ONGC, URAN | K17: =SUMMARY!J139*SUMMARY!E7+'02 & 04_0.02 KL'!I139+'02 & 04_0.02 KL'!I139+'03_0.330 KL'!I139+'03_0.330 KL'!I139+'05_0.942 KL'!I140*SUMMARY!E11 -> 57000
B19: TOTAL | D19: =SUM(D17:D18) -> 1000 | E19: KG | I19: COST WITHOUT TRANSPORT | K19: SALE WITHOUT TRANSPORT | L19: FACT. | N19: SALE WITHOUT TRANSPORT | O19: FACT.
B20: 3 mm PP | D20: =CEILING((E7*'01_1.35 KL'!D123)+(E8*'02 & 04_0.02 KL'!D123)+(SUMMARY!E9*'03_0.330 KL'!D123)+(SUMMARY!E10*'02 & 04_0.02 KL'!D123)+(SUMMARY!E11*'05_0.942 KL'!D124)+(SUMMARY!E12*'03_0.330 KL'!D123),1) -> 92 | E20: SQM | I20: =I13 -> 599641.01 | K20: =K13*0.9-K17 -> 1221000 | L20: =I20/K20 -> 0.49110648 | N20: =N13-K17 -> 1210000 | O20: =I20/N20 -> 0.49557108

Sheet ANNEXURE
B2: ANNEXURE : FRP TANKS & ABSORBER DTD. R1 21.12.2021 | F2: =B2 -> ANNEXURE : FRP TANKS & ABSORBER DTD. R1 21.12.2021
B3: CLIENT : PARAMOUNT LTD., VADODARA | F3: =B3 -> CLIENT : PARAMOUNT LTD., VADODARA
B4: PROJECT : ADDN. PROCESS UNITS, URAN (JOB NO : PL-637) | F4: =B4 -> PROJECT : ADDN. PROCESS UNITS, URAN (JOB NO : PL-637)
B5: OFFER NO. : OFFER/JRF/PL/21-22/O-630 R1 DTD. R1 21.12.2021 | F5: =B5 -> OFFER NO. : OFFER/JRF/PL/21-22/O-630 R1 DTD. R1 21.12.2021
B7: SR. NO | C7: 01 | D7: 02 | E7: 03 | F7: =B7 -> SR. NO | G7: 04 | H7: 05 | I7: 06
B8: TAG NO. | C8: 21-T-005 A/B | D8: 21-FB-02 B | E8: 21-T-006 A/B | F8: =B8 -> TAG NO. | G8: 21-FB-03 | H8: 21-T-007 A/B | I8: 21-T-008 A/B
B9: DOC.NO. | C9: ONGC-637-MDS-501-1 REV '1' | D9: ONGC-637-MDS-501-2 REV '1' | E9: ONGC-637-MDS-501-3 REV '1' | F9: =B9 -> DOC.NO. | G9: ONGC-637-MDS-501-4 REV '1' | H9: ONGC-637-MDS-501-5 REV '1' | I9: ONGC-637-MDS-501-6 REV '1'
B10: TITLE | C10: ACID MEASURING TANK (SAC) | D10: FUME ABSORBER FOR ACID MEASURING TANK (SAC) | E10: ACID MEASURING TANK (MB) | F10: =B10 -> TITLE | G10: FUME ABSORBER FOR ACID MEASURING TANK (MB) | H10: ALKALI MEASURING TANK (SBA) | I10: ALKALI MEASURING TANK (MB)
B11: TYPE | C11: VERTICAL CYLINDRICAL WITH FLANGE BOLTED WITH COVER AT TOP AND FLAT BOTTOM | D11: VERTICAL CYLINDRICAL WITH FLANGE BOLTED WITH COVER AT TOP AND FLAT BOTTOM | E11: VERTICAL CYLINDRICAL WITH FLANGE BOLTED WITH COVER AT TOP AND FLAT BOTTOM | F11: =B11 -> TYPE | G11: VERTICAL CYLINDRICAL WITH FLANGE BOLTED WITH COVER AT TOP AND FLAT BOTTOM | H11: VERTICAL CYLINDRICAL WITH FLANGE BOLTED WITH COVER AT TOP AND FLAT BOTTOM | I11: VERTICAL CYLINDRICAL WITH FLANGE BOLTED WITH COVER AT TOP AND FLAT BOTTOM
B12: SIZE (mm) | C12: 1200 mm ID X 1200 mm VERTICAL SHELL HT. | D12: 300 mm ID X 300 mm VERTICAL SHELL HT. | E12: 600 mm ID X 1200 mm VERTICAL SHELL HT. | F12: =B12 -> SIZE (mm) | G12: 300 mm ID X 300 mm VERTICAL SHELL HT. | H12: 1000 mm ID X 1000 mm VERTICAL SHELL HT. | I12: 600 mm ID X 1200 mm VERTICAL SHELL HT.
B13: CAPACITY | C13: 1.35 KL | D13: 0.021 KL | E13: 0.330 KL | F13: =B13 -> CAPACITY | G13: 0.021 KL | H13: 0.942 KL | I13: 0.330 KL
B14: DENSITY (KG/M3) | C14: 1150 | D14: 1140 | E14: 1150 | F14: =B14 -> DENSITY (KG/M3) | G14: 1140 | H14: 1330 | I14: 1330
B15: PROCESS FLUID | C15: 30 % HCl | D15: 30 % HCl | E15: 30 % HCl | F15: =B15 -> PROCESS FLUID | G15: 30 % HCl | H15: 30 % CAUSTIC SOLUTION | I15: 30 % CAUSTIC SOLUTION
B16: DESIGN PRESSURE | C16: ATM + FULL OF LIQUID | D16: ATMOSPHERIC | E16: ATM + FULL OF LIQUID | F16: =B16 -> DESIGN PRESSURE | G16: ATMOSPHERIC | H16: ATM + FULL OF LIQUID | I16: ATM + FULL OF LIQUID
B17: OP.PRESSURE _Kg/cm2g | C17: ATM + LIQUID UPTO OVERFLOW LEVEL | D17: ATM + LIQUID UPTO OVERFLOW LEVEL | E17: ATM + LIQUID UPTO OVERFLOW LEVEL | F17: =B17 -> OP.PRESSURE _Kg/cm2g | G17: ATMOSPHERIC | H17: ATM + LIQUID UPTO OVERFLOW LEVEL | I17: ATM + LIQUID UPTO OVERFLOW LEVEL
B18: DESIGN TEMP | C18: 65 DEG C | D18: AMBIENT | E18: 65 DEG C | F18: =B18 -> DESIGN TEMP | G18: AMBIENT | H18: 65 DEG C | I18: 65 DEG C
B19: OPERATING TEMP | C19: AMBIENT | D19: AMBIENT | E19: AMBIENT | F19: =B19 -> OPERATING TEMP | G19: AMBIENT | H19: AMBIENT | I19: AMBIENT
B20: DESIGN VACCUM PRESSURE | C20: - | D20: - | E20: - | F20: =B20 -> DESIGN VACCUM PRESSURE | G20: - | H20: - | I20: -
B21: HYDRO TEST | C21: FULL OF WATER | D21: FULL OF WATER | E21: FULL OF WATER | F21: =B21 -> HYDRO TEST | G21: FULL OF WATER | H21: FULL OF WATER | I21: FULL OF WATER
B22: DESIGN CODE | C22: BS 4994 | D22: BS 4994 | E22: BS 4994 | F22: =B22 -> DESIGN CODE | G22: BS 4994 | H22: BS 4994 | I22: BS 4994
B23: M.O.C | C23: FRP (BISPHENOL) | D23: FRP (BISPHENOL) | E23: FRP (BISPHENOL) | F23: =B23 -> M.O.C | G23: FRP (BISPHENOL) | H23: FRP (BISPHENOL) | I23: FRP (BISPHENOL)
B24: GASKET | C24: EPDM 3 mm THK | D24: EPDM 3 mm THK | E24: EPDM 3 mm THK | F24: =B24 -> GASKET | G24: EPDM 3 mm THK | H24: EPDM 3 mm THK | I24: EPDM 3 mm THK
B25: NUT BOLTS | C25: SS 316 / IS1367 CI 4.6/4.0 | D25: SS 316 / IS1367 CI 4.6/4.0 | E25: SS 316 / IS1367 CI 4.6/4.0 | F25: =B25 -> NUT BOLTS | G25: SS 316 / IS1367 CI 4.6/4.0 | H25: SS 316 / IS1367 CI 4.6/4.0 | I25: SS 316 / IS1367 CI 4.6/4.0
B26: THICKNESS | F26: =B26 -> THICKNESS
B27: SHELL | C27: 8 mm FRP | D27: 6 mm FRP | E27: 8 mm FRP | F27: =B27 -> SHELL | G27: 6 mm FRP | H27: 8 mm FRP | I27: 8 mm FRP
B28: BOTTOM FLAT | C28: 8 mm FRP | D28: 6 mm FRP | E28: 8 mm FRP | F28: =B28 -> BOTTOM FLAT | G28: 6 mm FRP | H28: 8 mm FRP | I28: 8 mm FRP
B29: TOP COVER | C29: 20 mm FRP | D29: 10 mm FRP | E29: 15 mm FRP | F29: =B29 -> TOP COVER | G29: 10 mm FRP | H29: 18 mm FRP | I29: 15 mm FRP
B30: BODY FLG | C30: 20 mm FRP | D30: 10 mm FRP | E30: 15 mm FRP | F30: =B30 -> BODY FLG | G30: 10 mm FRP | H30: 18 mm FRP | I30: 15 mm FRP
B31: NOZZLES | C31: AS PER YOUR SPECIFICATION SHEET | D31: AS PER YOUR SPECIFICATION SHEET | E31: AS PER YOUR SPECIFICATION SHEET | F31: =B31 -> NOZZLES | G31: AS PER YOUR SPECIFICATION SHEET | H31: AS PER YOUR SPECIFICATION SHEET | I31: AS PER YOUR SPECIFICATION SHEET
B32: FLANGE STD. | C32: ASME B 16.5 150 # | D32: ASME B 16.5 150 # | E32: ASME B 16.5 150 # | F32: =B32 -> FLANGE STD. | G32: ASME B 16.5 150 # | H32: ASME B 16.5 150 # | I32: ASME B 16.5 150 #
B33: INTERNALS | C33: BY CLIENT | D33: 1 NO. 40 NB PIPE IN FRP 1 NO. 25 NB WATER INLET WITH SPRY PORTION AS PER DRAWING | E33: BY CLIENT | F33: =B33 -> INTERNALS | G33: 1 NO. 40 NB PIPE IN FRP 1 NO. 25 NB WATER INLET WITH SPRY PORTION AS PER DRAWING | H33: BY CLIENT | I33: BY CLIENT
B34: ACCESSORIES | C34: 1 NO. NAME PLATE, 1 SET OF LIFTING LUGS, 1 SET OF HOLD DOWN LUGS, 1 No 12 THK.SUITABLE NATURAL RUBBER PADDING AT BOTTOM 1 SET OF ANCHOR BOLTS | D34: 1 NO. NAME PLATE, 1 SET OF LIFTING LUGS, 1 SET OF HOLD DOWN LUGS, 1 NO. 2 INCH BOTTOM PIPE SUPPORT WITH GUSSETS & BOTTOM SQUARE PLATE IN FRP 1 SET OF ANCHOR BOLTS | E34: 1 NO. NAME PLATE, 1 SET OF LIFTING LUGS, 1 SET OF HOLD DOWN LUGS, 1 No 12 THK.SUITABLE NATURAL RUBBER PADDING AT BOTTOM 1 SET OF ANCHOR BOLTS | F34: =B34 -> ACCESSORIES | G34: 1 NO. NAME PLATE, 1 SET OF LIFTING LUGS, 1 SET OF HOLD DOWN LUGS, 1 NO. 2 INCH BOTTOM PIPE SUPPORT WITH GUSSETS & BOTTOM SQUARE PLATE IN FRP 1 SET OF ANCHOR BOLTS | H34: 1 NO. NAME PLATE, 1 SET OF LIFTING LUGS, 1 SET OF HOLD DOWN LUGS, 1 No 12 THK.SUITABLE NATURAL RUBBER PADDING AT BOTTOM 1 SET OF ANCHOR BOLTS IN MS 4 NO'S BAFFLES IN FRP | I34: 1 NO. NAME PLATE, 1 SET OF LIFTING LUGS, 1 SET OF HOLD DOWN LUGS, 1 No 12 THK.SUITABLE NATURAL RUBBER PADDING AT BOTTOM 1 SET OF ANCHOR BOLTS 4 NO'S BAFFLES IN FRP
B35: SUPPORT | C35: NIL, SELF SUPPORTED (CLIENT TO PROVIDE FINE CEMENT SLURRY OVER THE CIVIL FOUNDATION AT THE TIME OF INSTALLATION OF TANK) | D35: FRP PIPE SUPPORT AS PER SHOWN IN DRAWING, CIVIL FOUNDATION BY CLIENT | E35: NIL, SELF SUPPORTED (CLIENT TO PROVIDE FINE CEMENT SLURRY OVER THE CIVIL FOUNDATION AT THE TIME OF INSTALLATION OF TANK) | F35: =B35 -> SUPPORT | G35: FRP PIPE SUPPORT AS PER SHOWN IN DRAWING, CIVIL FOUNDATION BY CLIENT | H35: NIL, SELF SUPPORTED (CLIENT TO PROVIDE FINE CEMENT SLURRY OVER THE CIVIL FOUNDATION AT THE TIME OF INSTALLATION OF TANK) | I35: NIL, SELF SUPPORTED (CLIENT TO PROVIDE FINE CEMENT SLURRY OVER THE CIVIL FOUNDATION AT THE TIME OF INSTALLATION OF TANK)
B36: COMMISSIONING SPARES | C36: As a minimum 200 % gaskets and 10 % (2 sets min.) Studs and nuts for all blinded nozzles and Manhole | D36: As a minimum 200 % gaskets and 10 % (2 sets min.) Studs and nuts for all blinded nozzles and Manhole | E36: As a minimum 200 % gaskets and 10 % (2 sets min.) Studs and nuts for all blinded nozzles and Manhole | F36: =B36 -> COMMISSIONING SPARES | G36: As a minimum 200 % gaskets and 10 % (2 sets min.) Studs and nuts for all blinded nozzles and Manhole | H36: As a minimum 200 % gaskets and 10 % (2 sets min.) Studs and nuts for all blinded nozzles and Manhole | I36: As a minimum 200 % gaskets and 10 % (2 sets min.) Studs and nuts for all blinded nozzles and Manhole
B37: EXCLUSION | C37: LI/LT/TI /TT/PI/PTT, LADDER & RAILING, THERMOWELL , EARTHING BOSS, GRAPHITE ROD ASSEMBLY, SUPPORT STURCURE & ITS ACCESSORIES, ANY TYPE OF VALVES & INSTRUMENTS, ANY TYPE OF INSULATION, ANY OTHER ITEM OR SERVICE NOT SPECIALLY MENTIONED ABOVE | D37: LI/LT/TI /TT/PI/PTT, LADDER & RAILING, THERMOWELL , EARTHING BOSS, GRAPHITE ROD ASSEMBLY, SUPPORT STURCURE & ITS ACCESSORIES, ANY TYPE OF VALVES & INSTRUMENTS, ANY TYPE OF INSULATION, ANY OTHER ITEM OR SERVICE NOT SPECIALLY MENTIONED ABOVE | E37: LI/LT/TI /TT/PI/PTT, LADDER & RAILING, THERMOWELL , EARTHING BOSS, GRAPHITE ROD ASSEMBLY, SUPPORT STURCURE & ITS ACCESSORIES, ANY TYPE OF VALVES & INSTRUMENTS, ANY TYPE OF INSULATION, ANY OTHER ITEM OR SERVICE NOT SPECIALLY MENTIONED ABOVE | F37: =B37 -> EXCLUSION | G37: LI/LT/TI /TT/PI/PTT, LADDER & RAILING, THERMOWELL , EARTHING BOSS, GRAPHITE ROD ASSEMBLY, SUPPORT STURCURE & ITS ACCESSORIES, ANY TYPE OF VALVES & INSTRUMENTS, ANY TYPE OF INSULATION, ANY OTHER ITEM OR SERVICE NOT SPECIALLY MENTIONED ABOVE | H37: LI/LT/TI /TT/PI/PTT, LADDER & RAILING, THERMOWELL , EARTHING BOSS, GRAPHITE ROD ASSEMBLY, SUPPORT STURCURE & ITS ACCESSORIES, ANY TYPE OF VALVES & INSTRUMENTS, ANY TYPE OF INSULATION, ANY OTHER ITEM OR SERVICE NOT SPECIALLY MENTIONED ABOVE | I37: LI/LT/TI /TT/PI/PTT, LADDER & RAILING, THERMOWELL , EARTHING BOSS, GRAPHITE ROD ASSEMBLY, SUPPORT STURCURE & ITS ACCESSORIES, ANY TYPE OF VALVES & INSTRUMENTS, ANY TYPE OF INSULATION, ANY OTHER ITEM OR SERVICE NOT SPECIALLY MENTIONED ABOVE
B38: UNIT RATE (Rs.) | C38: ='01_1.35 KL'!I142 -> 203000 | D38: ='02 & 04_0.02 KL'!I142 -> 46500 | E38: ='03_0.330 KL'!I142 -> 107000 | F38: =B38 -> UNIT RATE (Rs.) | G38: ='02 & 04_0.02 KL'!I142 -> 46500 | H38: ='05_0.942 KL'!I143 -> 186000 | I38: ='06_0.330 KL'!I143 -> 121000 | J38: TOTAL
B39: QTY (NOS) | C39: 2 | D39: 2 | E39: 2 | F39: =B39 -> QTY (NOS) | G39: 2 | H39: 2 | I39: 2 | J39: =SUM(C39:I39) -> 12
B40: TOTAL (Rs.) | C40: =C38*C39 -> 406000 | D40: =D38*D39 -> 93000 | E40: =E38*E39 -> 214000 | F40: =B40 -> TOTAL (Rs.) | G40: =G38*G39 -> 93000 | H40: =H38*H39 -> 372000 | I40: =I38*I39 -> 242000 | J40: =SUM(C40:I40) -> 1420000
B41: NOTE | C41: MATRIAL SUITABLITY TO BE CHECK AT YOUR END | F41: =B41 -> NOTE | G41: MATRIAL SUITABLITY TO BE CHECK AT YOUR END
C42: 01 | D42: 02 | E42: 03 | G42: 04 | H42: 05 | I42: 06
...

Sheet 01_1.35 KL
C1: DATE | D1: 44551 | E1: R1
C2: DATE | D2: 44530 | E2: R0 | M2: R1 | N2: 01
C3: TYPE | D3: VERTICAL CYLINDRICAL WITH FLAT TOP WITH COVER AND FLAT BOTTOM
C4: CLIENT | D4: M/s PARAMOUNT
C5: CAPACITY | D5: =M11 -> 1.357168 | E5: KL
C6: TITLE | D6: ACID MEASURING TANK (SAC)
C10: DIAMETER | D10: =+J13/1000 -> 1.2 | F10: 21-T-005 A/B
C11: HEIGHT | D11: =+I13/1000 -> 1.2 | M11: =(PI()/4)*(DIA^2)*HT -> 1.357168
C12: CONE ANGLE | D12: 15 | I12: HEIGHT | J12: DIAMETER
C13: B. SHELL HT. | D13: =+HT/5 -> 0.24 | I13: 1200 | J13: 1200
C14: B.M. SHELL HT. | D14: =+HT/5 -> 0.24 | I14: (in mm) | J14: (in mm)
C15: M. SHELL HT. | D15: =+HT/5 -> 0.24
C16: T.M. SHELL HT. | D16: =+HT/5 -> 0.24
C17: T. SHELL HT. | D17: =+HT/5 -> 0.24
C18: D.E.D | D18: =+DIA*1.2+0.1 -> 1.54
D20: M.O.C- FRP (BISPHENOL)
D21: THK | H21: PART | I21: Qty | J21: =D22 -> 0 | K21: FRP AREA | L21: =E22 -> BIS | M21: =F22 -> BIS | N21: =G22 -> BIS
C22: THK | E22: BIS | F22: BIS | G22: BIS | J22: Sq.M | K22: Sq.M | L22: Sq.M-mm | M22: Sq.M-mm | N22: Sq.M-mm
C23: 8 | E23: 3 | F23: =C23-E23-G23 -> 4 | G23: 1 | H23: BOTTOM SHELL | I23: 1 | J23: =PI()*DIA*D13*I23 -> 0.90477868 | K23: =PI()*DIA*D13 -> 0.90477868 | L23: =K23*E23*I23 -> 2.7143361 | M23: =K23*F23*I23 -> 3.6191147 | N23: =K23*G23*I23 -> 0.90477868
C24: 8 | E24: 3 | F24: =C24-E24-G24 -> 4 | G24: 1 | H24: BOTT MIDD SHELL | I24: 1 | J24: =PI()*DIA*B.M.S.H*I24 -> 0.90477868 | K24: =PI()*DIA*B.M.S.H -> 0.90477868 | L24: =K24*E24*I24 -> 2.7143361 | M24: =K24*F24*I24 -> 3.6191147 | N24: =K24*G24*I24 -> 0.90477868
C25: 8 | E25: 3 | F25: =C25-E25-G25 -> 4 | G25: 1 | H25: MIDDLE SHELL | I25: 1 | J25: =PI()*DIA*M.S.H*I25 -> 0.90477868 | K25: =PI()*DIA*M.S.H -> 0.90477868 | L25: =K25*E25*I25 -> 2.7143361 | M25: =K25*F25*I25 -> 3.6191147 | N25: =K25*G25*I25 -> 0.90477868
C26: 8 | E26: 3 | F26: =C26-E26-G26 -> 4 | G26: 1 | H26: TOP MIDD SHELL | I26: 1 | J26: =PI()*DIA*T.M.S.H*I26 -> 0.90477868 | K26: =PI()*DIA*T.M.S.H -> 0.90477868 | L26: =K26*E26*I26 -> 2.7143361 | M26: =K26*F26*I26 -> 3.6191147 | N26: =K26*G26*I26 -> 0.90477868
C27: 8 | E27: 3 | F27: =C27-E27-G27 -> 4 | G27: 1 | H27: TOP SHELL | I27: 1 | J27: =PI()*DIA*T.S.H*I27 -> 0.90477868 | K27: =PI()*DIA*T.S.H -> 0.90477868 | L27: =K27*E27*I27 -> 2.7143361 | M27: =K27*F27*I27 -> 3.6191147 | N27: =K27*G27*I27 -> 0.90477868
C28: 8 | E28: 0 | F28: 0 | G28: 0 | H28: CON TOP | I28: 1 | J28: =((DIA^2)/(COS(ANGLE*PI()/180)))*I28 -> 1.4907977 | K28: =PI()/4*((DIA^2)/(COS(ANGLE*PI()/180))) -> 1.1708698 | L28: =K28*E28*I28 -> 0 | M28: =K28*F28*I28 -> 0 | N28: =K28*G28*I28 -> 0
C29: 8 | E29: 3 | F29: =C29-E29-G29 -> 4 | G29: 1 | H29: FLAT BOTTM | I29: 1 | J29: =(DIA^2)*I29 -> 1.44 | K29: =(PI()/4)*(DIA^2) -> 1.1309734 | L29: =K29*E29*I29 -> 3.3929201 | M29: =K29*F29*I29 -> 4.5238934 | N29: =K29*G29*I29 -> 1.1309734
C30: 20 | E30: 3 | F30: =C30-E30-G30 -> 16 | G30: 1 | H30: BODY FLG | I30: 1 | J30: =((DIA+0.2)^2)*I30 -> 1.96 | K30: =((PI()/4)*((DIA+0.2)^2-DIA^2)) -> 0.40840704 | L30: =K30*E30*I30 -> 1.2252211 | M30: =K30*F30*I30 -> 6.5345127 | N30: =K30*G30*I30 -> 0.40840704
C31: 20 | E31: 3 | F31: =C31-E31-G31 -> 16 | G31: 1 | H31: TOP COVER | I31: 1 | J31: =((DIA+0.2)^2)*I31 -> 1.96 | K31: =((PI()/4)*((DIA+0.2)^2)) -> 1.5393804 | L31: =K31*E31*I31 -> 4.6181412 | M31: =K31*F31*I31 -> 24.630086 | N31: =K31*G31*I31 -> 1.5393804
C32: =CEILING((C31+C23)*0.5,1) -> 14 | F32: =C32-E32-G32 -> 14 | H32: R/F - BOTTOM | I32: 1 | K32: =PI()*DIA*(2*2*SQRT(DIA*((C32)/1000/2))) -> 1.3820723 | M32: =K32*F32*I32 -> 19.349012
C33: =CEILING((C31+C27)*0.5,1) -> 14 | F33: =C33-E33-G33 -> 14 | H33: R/F - TOP | I33: 1 | K33: =PI()*DIA*(2*2*SQRT(DIA*((C33)/1000/2))) -> 1.3820723 | M33: =K33*F33*I33 -> 19.349012
C34: 0 | F34: =C34-E34-G34 -> 0 | H34: R/F -LUGS SUPPORT | I34: 1 | K34: =PI()*DIA*0.45 -> 1.69646 | M34: =K34*F34*I34 -> 0
C35: 0 | F35: =C35-E35-G35 -> 0 | H35: STFFENER @TOP | I35: 0 | K35: =(DIA)/(COS(ANGLE*PI()/180))*((50+75+75+75+50)/1000) -> 0.40375771 | M35: =K35*F35*I35 -> 0
C36: 0 | F36: =C36-E36-G36 -> 0 | H36: SHEL STIFF | I36: 0 | K36: =PI()*DIA*0.4 -> 1.5079645 | M36: =K36*F36*I36 -> 0
V37: FLG. THICKNESS | X37: PIPE THICKNESS | Z37: FLG. AREA | AB37: PIPE AREA | AD37: TOTAL
Q38: NOZZLE | R38: PIPE SIZE | S38: PIPE LENGTH | T38: FLG. OD | U38: AREA | V38: PP | W38: FRP | X38: PP | Y38: FRP | Z38: PP | AA38: FRP | AB38: PP | AC38: FRP | AD38: PP (Sq.M) | AE38: FRP (Sq. M- mm)
P39: N001 | Q39: N001 | R39: 0 | S39: 0 | T39: 0 | U39: =((PI()/4)*(T39^2-R39^2))+(PI()*R39*S39) -> 0 | V39: 5 | W39: 12 | X39: 5 | Y39: 5 | Z39: =(T39^2)*CEILING(V39/4,1) -> 0 | AA39: =((PI()/4)*(T39^2-R39^2))*W39 -> 0 | AB39: =+(PI()*R39*S39)*CEILING(X39/3,1) -> 0 | AC39: =+(PI()*R39*S39)*Y39 -> 0 | AD39: =+Z39+AB39 -> 0 | AE39: =+AA39+AC39 -> 0
H40: N040 | I40: 4 | J40: =LOOKUP(H40,NOZZLE1,PP_AREA)*I40 -> 0.27982845 | L40: 1.39 | M40: =L40*I40 -> 5.56 | P40: N015 | Q40: N015 | R40: 0.015 | S40: 0.15 | T40: 0.089 | U40: =((PI()/4)*(T40^2-R40^2))+(PI()*R40*S40) -> 0.013113008 | V40: 5 | W40: 12 | X40: 5 | Y40: 5 | Z40: =(T40^2)*CEILING(V40/4,1) -> 0.015842 | AA40: =((PI()/4)*(T40^2-R40^2))*W40 -> 0.072533091 | AB40: =+(PI()*R40*S40)*CEILING(X40/3,1) -> 0.014137167 | AC40: =+(PI()*R40*S40)*Y40 -> 0.035342917 | AD40: =+Z40+AB40 -> 0.029979167 | AE40: =+AA40+AC40 -> 0.10787601
H41: N050 | I41: 2 | J41: =LOOKUP(H41,NOZZLE1,PP_AREA)*I41 -> 0.18666378 | L41: 1.7 | M41: =L41*I41 -> 3.4 | P41: N020 | Q41: N020 | R41: 0.02 | S41: 0.15 | T41: 0.098 | U41: =((PI()/4)*(T41^2-R41^2))+(PI()*R41*S41) -> 0.016653583 | V41: 5 | W41: 12 | X41: 5 | Y41: 5 | Z41: =(T41^2)*CEILING(V41/4,1) -> 0.019208 | AA41: =((PI()/4)*(T41^2-R41^2))*W41 -> 0.086745656 | AB41: =+(PI()*R41*S41)*CEILING(X41/3,1) -> 0.018849556 | AC41: =+(PI()*R41*S41)*Y41 -> 0.04712389 | AD41: =+Z41+AB41 -> 0.038057556 | AE41: =+AA41+AC41 -> 0.13386955
H42: N100 | I42: 3 | J42: =LOOKUP(H42,NOZZLE1,PP_AREA)*I42 -> 0.59738934 | L42: 1.9 | M42: =L42*I42 -> 5.7 | P42: N025 | Q42: N025 | R42: 0.025 | S42: 0.15 | T42: 0.108 | U42: =((PI()/4)*(T42^2-R42^2))+(PI()*R42*S42) -> 0.020450983 | V42: 5 | W42: 12 | X42: 5 | Y42: 5 | Z42: =(T42^2)*CEILING(V42/4,1) -> 0.023328 | AA42: =((PI()/4)*(T42^2-R42^2))*W42 -> 0.10404012 | AB42: =+(PI()*R42*S42)*CEILING(X42/3,1) -> 0.023561945 | AC42: =+(PI()*R42*S42)*Y42 -> 0.058904862 | AD42: =+Z42+AB42 -> 0.046889945 | AE42: =+AA42+AC42 -> 0.16294499
H43: N100 | I43: 0 | J43: =LOOKUP(H43,NOZZLE1,PP_AREA)*I43 -> 0 | L43: 1.55 | M43: =L43*I43 -> 0 | P43: N040 | Q43: N040 | R43: 0.04 | S43: 0.15 | T43: 0.127 | U43: =((PI()/4)*(T43^2-R43^2))+(PI()*R43*S43) -> 0.030260606 | V43: 5 | W43: 15 | X43: 5 | Y43: 6 | Z43: =(T43^2)*CEILING(V43/4,1) -> 0.032258 | AA43: =((PI()/4)*(T43^2-R43^2))*W43 -> 0.17116575 | AB43: =+(PI()*R43*S43)*CEILING(X43/3,1) -> 0.037699112 | AC43: =+(PI()*R43*S43)*Y43 -> 0.11309734 | AD43: =+Z43+AB43 -> 0.069957112 | AE43: =+AA43+AC43 -> 0.28426308
H44: N450 | I44: 0 | J44: =LOOKUP(H44,NOZZLE1,PP_AREA)*I44 -> 0 | L44: 7.34 | M44: =L44*I44 -> 0 | P44: N050 | Q44: N050 | R44: 0.05 | S44: 0.15 | T44: 0.152 | U44: =((PI()/4)*(T44^2-R44^2))+(PI()*R44*S44) -> 0.039744289 | V44: 5 | W44: 15 | X44: 5 | Y44: 6 | Z44: =(T44^2)*CEILING(V44/4,1) -> 0.046208 | AA44: =((PI()/4)*(T44^2-R44^2))*W44 -> 0.24273516 | AB44: =+(PI()*R44*S44)*CEILING(X44/3,1) -> 0.04712389 | AC44: =+(PI()*R44*S44)*Y44 -> 0.14137167 | AD44: =+Z44+AB44 -> 0.09333189 | AE44: =+AA44+AC44 -> 0.38410683
...

Sheet 02 & 04_0.02 KL
C1: DATE | D1: ='01_1.35 KL'!D1 -> 44551 | E1: R1
C2: DATE | D2: ='01_1.35 KL'!D2 -> 44530 | E2: R0 | M2: ='01_1.35 KL'!M2:M4 -> R1 | N2: 02 & 04
C3: TYPE | D3: VERTICAL CYLINDRICAL WITH FLAT TOP WITH COVER AND FLAT BOTTOM
C4: CLIENT | D4: M/s PARAMOUNT
C5: CAPACITY | D5: =M11 -> 0.02120575 | E5: KL
C6: TITLE | D6: FUME ABSORBER FOR (SAC)
C10: DIAMETER | D10: =+J13/1000 -> 0.3 | F10: 21-FB-02 B
C11: HEIGHT | D11: =+I13/1000 -> 0.3 | M11: =(PI()/4)*(DIA^2)*HT -> 0.02120575
C12: CONE ANGLE | D12: 15 | I12: HEIGHT | J12: DIAMETER
C13: B. SHELL HT. | D13: =+HT/5 -> 0.06 | I13: 300 | J13: 300
C14: B.M. SHELL HT. | D14: =+HT/5 -> 0.06 | I14: (in mm) | J14: (in mm)
C15: M. SHELL HT. | D15: =+HT/5 -> 0.06
C16: T.M. SHELL HT. | D16: =+HT/5 -> 0.06
C17: T. SHELL HT. | D17: =+HT/5 -> 0.06
C18: D.E.D | D18: =+DIA*1.2+0.1 -> 0.46
D20: M.O.C- FRP (BISPHENOL)
D21: THK | H21: PART | I21: Qty | J21: =D22 -> 0 | K21: FRP AREA | L21: =E22 -> BIS | M21: =F22 -> BIS | N21: =G22 -> BIS
C22: THK | E22: BIS | F22: BIS | G22: BIS | J22: Sq.M | K22: Sq.M | L22: Sq.M-mm | M22: Sq.M-mm | N22: Sq.M-mm
C23: 6 | E23: 3 | F23: =C23-E23-G23 -> 2 | G23: 1 | H23: BOTTOM SHELL | I23: 1 | J23: =PI()*DIA*D13*I23 -> 0.056548668 | K23: =PI()*DIA*D13 -> 0.056548668 | L23: =K23*E23*I23 -> 0.169646 | M23: =K23*F23*I23 -> 0.11309734 | N23: =K23*G23*I23 -> 0.056548668
C24: 6 | E24: 3 | F24: =C24-E24-G24 -> 2 | G24: 1 | H24: BOTT MIDD SHELL | I24: 1 | J24: =PI()*DIA*B.M.S.H*I24 -> 0.056548668 | K24: =PI()*DIA*B.M.S.H -> 0.056548668 | L24: =K24*E24*I24 -> 0.169646 | M24: =K24*F24*I24 -> 0.11309734 | N24: =K24*G24*I24 -> 0.056548668
C25: 6 | E25: 3 | F25: =C25-E25-G25 -> 2 | G25: 1 | H25: MIDDLE SHELL | I25: 1 | J25: =PI()*DIA*M.S.H*I25 -> 0.056548668 | K25: =PI()*DIA*M.S.H -> 0.056548668 | L25: =K25*E25*I25 -> 0.169646 | M25: =K25*F25*I25 -> 0.11309734 | N25: =K25*G25*I25 -> 0.056548668
C26: 6 | E26: 3 | F26: =C26-E26-G26 -> 2 | G26: 1 | H26: TOP MIDD SHELL | I26: 1 | J26: =PI()*DIA*T.M.S.H*I26 -> 0.056548668 | K26: =PI()*DIA*T.M.S.H -> 0.056548668 | L26: =K26*E26*I26 -> 0.169646 | M26: =K26*F26*I26 -> 0.11309734 | N26: =K26*G26*I26 -> 0.056548668
C27: 6 | E27: 3 | F27: =C27-E27-G27 -> 2 | G27: 1 | H27: TOP SHELL | I27: 1 | J27: =PI()*DIA*T.S.H*I27 -> 0.056548668 | K27: =PI()*DIA*T.S.H -> 0.056548668 | L27: =K27*E27*I27 -> 0.169646 | M27: =K27*F27*I27 -> 0.11309734 | N27: =K27*G27*I27 -> 0.056548668
C28: 6 | E28: 0 | F28: 0 | G28: 0 | H28: CON TOP | I28: 1 | J28: =((DIA^2)/(COS(ANGLE*PI()/180)))*I28 -> 0.093174856 | K28: =PI()/4*((DIA^2)/(COS(ANGLE*PI()/180))) -> 0.073179361 | L28: =K28*E28*I28 -> 0 | M28: =K28*F28*I28 -> 0 | N28: =K28*G28*I28 -> 0
C29: 6 | E29: 3 | F29: =C29-E29-G29 -> 2 | G29: 1 | H29: FLAT BOTTM | I29: 1 | J29: =(DIA^2)*I29 -> 0.09 | K29: =(PI()/4)*(DIA^2) -> 0.070685835 | L29: =K29*E29*I29 -> 0.2120575 | M29: =K29*F29*I29 -> 0.14137167 | N29: =K29*G29*I29 -> 0.070685835
C30: 10 | E30: 3 | F30: =C30-E30-G30 -> 6 | G30: 1 | H30: BODY FLG | I30: 1 | J30: =((DIA+0.2)^2)*I30 -> 0.25 | K30: =((PI()/4)*((DIA+0.2)^2-DIA^2)) -> 0.12566371 | L30: =K30*E30*I30 -> 0.37699112 | M30: =K30*F30*I30 -> 0.75398224 | N30: =K30*G30*I30 -> 0.12566371
C31: 10 | E31: 3 | F31: =C31-E31-G31 -> 6 | G31: 1 | H31: TOP COVER | I31: 1 | J31: =((DIA+0.2)^2)*I31 -> 0.25 | K31: =((PI()/4)*((DIA+0.2)^2)) -> 0.19634954 | L31: =K31*E31*I31 -> 0.58904862 | M31: =K31*F31*I31 -> 1.1780972 | N31: =K31*G31*I31 -> 0.19634954
C32: =CEILING((C31+C23)*0.5,1) -> 8 | F32: =C32-E32-G32 -> 8 | H32: R/F - BOTTOM | I32: 1 | K32: =PI()*DIA*(2*2*SQRT(DIA*((C32)/1000/2))) -> 0.13059355 | M32: =K32*F32*I32 -> 1.0447484
C33: =CEILING((C31+C27)*0.5,1) -> 8 | F33: =C33-E33-G33 -> 8 | H33: R/F - TOP | I33: 1 | K33: =PI()*DIA*(2*2*SQRT(DIA*((C33)/1000/2))) -> 0.13059355 | M33: =K33*F33*I33 -> 1.0447484
C34: 0 | F34: =C34-E34-G34 -> 0 | H34: R/F -LUGS SUPPORT | I34: 1 | K34: =PI()*DIA*0.45 -> 0.42411501 | M34: =K34*F34*I34 -> 0
C35: 0 | F35: =C35-E35-G35 -> 0 | H35: STFFENER @TOP | I35: 0 | K35: =(DIA)/(COS(ANGLE*PI()/180))*((50+75+75+75+50)/1000) -> 0.10093943 | M35: =K35*F35*I35 -> 0
C36: 0 | F36: =C36-E36-G36 -> 0 | H36: SHEL STIFF | I36: 0 | K36: =PI()*DIA*0.4 -> 0.37699112 | M36: =K36*F36*I36 -> 0
V37: FLG. THICKNESS | X37: PIPE THICKNESS | Z37: FLG. AREA | AB37: PIPE AREA | AD37: TOTAL
Q38: NOZZLE | R38: PIPE SIZE | S38: PIPE LENGTH | T38: FLG. OD | U38: AREA | V38: PP | W38: FRP | X38: PP | Y38: FRP | Z38: PP | AA38: FRP | AB38: PP | AC38: FRP | AD38: PP (Sq.M) | AE38: FRP (Sq. M- mm)
P39: N001 | Q39: N001 | R39: 0 | S39: 0 | T39: 0 | U39: =((PI()/4)*(T39^2-R39^2))+(PI()*R39*S39) -> 0 | V39: 5 | W39: 12 | X39: 5 | Y39: 5 | Z39: =(T39^2)*CEILING(V39/4,1) -> 0 | AA39: =((PI()/4)*(T39^2-R39^2))*W39 -> 0 | AB39: =+(PI()*R39*S39)*CEILING(X39/3,1) -> 0 | AC39: =+(PI()*R39*S39)*Y39 -> 0 | AD39: =+Z39+AB39 -> 0 | AE39: =+AA39+AC39 -> 0
H40: N025 | I40: 0 | J40: =LOOKUP(H40,NOZZLE1,PP_AREA)*I40 -> 0 | L40: 1.19 | M40: =L40*I40 -> 0 | P40: N015 | Q40: N015 | R40: 0.015 | S40: 0.15 | T40: 0.089 | U40: =((PI()/4)*(T40^2-R40^2))+(PI()*R40*S40) -> 0.013113008 | V40: 5 | W40: 12 | X40: 5 | Y40: 5 | Z40: =(T40^2)*CEILING(V40/4,1) -> 0.015842 | AA40: =((PI()/4)*(T40^2-R40^2))*W40 -> 0.072533091 | AB40: =+(PI()*R40*S40)*CEILING(X40/3,1) -> 0.014137167 | AC40: =+(PI()*R40*S40)*Y40 -> 0.035342917 | AD40: =+Z40+AB40 -> 0.029979167 | AE40: =+AA40+AC40 -> 0.10787601
H41: N040 | I41: 3 | J41: =LOOKUP(H41,NOZZLE1,PP_AREA)*I41 -> 0.20987134 | L41: 1.39 | M41: =L41*I41 -> 4.17 | P41: N020 | Q41: N020 | R41: 0.02 | S41: 0.15 | T41: 0.098 | U41: =((PI()/4)*(T41^2-R41^2))+(PI()*R41*S41) -> 0.016653583 | V41: 5 | W41: 12 | X41: 5 | Y41: 5 | Z41: =(T41^2)*CEILING(V41/4,1) -> 0.019208 | AA41: =((PI()/4)*(T41^2-R41^2))*W41 -> 0.086745656 | AB41: =+(PI()*R41*S41)*CEILING(X41/3,1) -> 0.018849556 | AC41: =+(PI()*R41*S41)*Y41 -> 0.04712389 | AD41: =+Z41+AB41 -> 0.038057556 | AE41: =+AA41+AC41 -> 0.13386955
H42: N200 | I42: 0 | J42: =LOOKUP(H42,NOZZLE1,PP_AREA)*I42 -> 0 | L42: 3.44 | M42: =L42*I42 -> 0 | P42: N025 | Q42: N025 | R42: 0.025 | S42: 0.15 | T42: 0.108 | U42: =((PI()/4)*(T42^2-R42^2))+(PI()*R42*S42) -> 0.020450983 | V42: 5 | W42: 12 | X42: 5 | Y42: 5 | Z42: =(T42^2)*CEILING(V42/4,1) -> 0.023328 | AA42: =((PI()/4)*(T42^2-R42^2))*W42 -> 0.10404012 | AB42: =+(PI()*R42*S42)*CEILING(X42/3,1) -> 0.023561945 | AC42: =+(PI()*R42*S42)*Y42 -> 0.058904862 | AD42: =+Z42+AB42 -> 0.046889945 | AE42: =+AA42+AC42 -> 0.16294499
H43: N100 | I43: 0 | J43: =LOOKUP(H43,NOZZLE1,PP_AREA)*I43 -> 0 | L43: 1.55 | M43: =L43*I43 -> 0 | P43: N040 | Q43: N040 | R43: 0.04 | S43: 0.15 | T43: 0.127 | U43: =((PI()/4)*(T43^2-R43^2))+(PI()*R43*S43) -> 0.030260606 | V43: 5 | W43: 15 | X43: 5 | Y43: 6 | Z43: =(T43^2)*CEILING(V43/4,1) -> 0.032258 | AA43: =((PI()/4)*(T43^2-R43^2))*W43 -> 0.17116575 | AB43: =+(PI()*R43*S43)*CEILING(X43/3,1) -> 0.037699112 | AC43: =+(PI()*R43*S43)*Y43 -> 0.11309734 | AD43: =+Z43+AB43 -> 0.069957112 | AE43: =+AA43+AC43 -> 0.28426308
H44: N450 | I44: 0 | J44: =LOOKUP(H44,NOZZLE1,PP_AREA)*I44 -> 0 | L44: 7.34 | M44: =L44*I44 -> 0 | P44: N050 | Q44: N050 | R44: 0.05 | S44: 0.15 | T44: 0.152 | U44: =((PI()/4)*(T44^2-R44^2))+(PI()*R44*S44) -> 0.039744289 | V44: 5 | W44: 15 | X44: 5 | Y44: 6 | Z44: =(T44^2)*CEILING(V44/4,1) -> 0.046208 | AA44: =((PI()/4)*(T44^2-R44^2))*W44 -> 0.24273516 | AB44: =+(PI()*R44*S44)*CEILING(X44/3,1) -> 0.04712389 | AC44: =+(PI()*R44*S44)*Y44 -> 0.14137167 | AD44: =+Z44+AB44 -> 0.09333189 | AE44: =+AA44+AC44 -> 0.38410683
...

Sheet 03_0.330 KL
C1: DATE | D1: ='01_1.35 KL'!D1 -> 44551 | E1: R1
C2: DATE | D2: ='01_1.35 KL'!D2 -> 44530 | E2: R0 | M2: ='01_1.35 KL'!M2:M4 -> R1 | N2: 03 & 06
C3: TYPE | D3: VERTICAL CYLINDRICAL WITH FLAT TOP WITH COVER AND FLAT BOTTOM
C4: CLIENT | D4: M/s PARAMOUNT
C5: CAPACITY | D5: =M11 -> 0.33929201 | E5: KL
C6: TITLE | D6: ACID MEASURING TANK (MB)
C10: DIAMETER | D10: =+J13/1000 -> 0.6 | F10: 21-T-006 A/B
C11: HEIGHT | D11: =+I13/1000 -> 1.2 | M11: =(PI()/4)*(DIA^2)*HT -> 0.33929201
C12: CONE ANGLE | D12: 15 | I12: HEIGHT | J12: DIAMETER
C13: B. SHELL HT. | D13: =+HT/5 -> 0.24 | I13: 1200 | J13: 600
C14: B.M. SHELL HT. | D14: =+HT/5 -> 0.24 | I14: (in mm) | J14: (in mm)
C15: M. SHELL HT. | D15: =+HT/5 -> 0.24
C16: T.M. SHELL HT. | D16: =+HT/5 -> 0.24
C17: T. SHELL HT. | D17: =+HT/5 -> 0.24
C18: D.E.D | D18: =+DIA*1.2+0.1 -> 0.82
D20: M.O.C- FRP (BISPHENOL)
D21: THK | H21: PART | I21: Qty | J21: =D22 -> 0 | K21: FRP AREA | L21: =E22 -> BIS | M21: =F22 -> BIS | N21: =G22 -> BIS
C22: THK | E22: BIS | F22: BIS | G22: BIS | J22: Sq.M | K22: Sq.M | L22: Sq.M-mm | M22: Sq.M-mm | N22: Sq.M-mm
C23: 8 | E23: 3 | F23: =C23-E23-G23 -> 4 | G23: 1 | H23: BOTTOM SHELL | I23: 1 | J23: =PI()*DIA*D13*I23 -> 0.45238934 | K23: =PI()*DIA*D13 -> 0.45238934 | L23: =K23*E23*I23 -> 1.357168 | M23: =K23*F23*I23 -> 1.8095574 | N23: =K23*G23*I23 -> 0.45238934
C24: 8 | E24: 3 | F24: =C24-E24-G24 -> 4 | G24: 1 | H24: BOTT MIDD SHELL | I24: 1 | J24: =PI()*DIA*B.M.S.H*I24 -> 0.45238934 | K24: =PI()*DIA*B.M.S.H -> 0.45238934 | L24: =K24*E24*I24 -> 1.357168 | M24: =K24*F24*I24 -> 1.8095574 | N24: =K24*G24*I24 -> 0.45238934
C25: 8 | E25: 3 | F25: =C25-E25-G25 -> 4 | G25: 1 | H25: MIDDLE SHELL | I25: 1 | J25: =PI()*DIA*M.S.H*I25 -> 0.45238934 | K25: =PI()*DIA*M.S.H -> 0.45238934 | L25: =K25*E25*I25 -> 1.357168 | M25: =K25*F25*I25 -> 1.8095574 | N25: =K25*G25*I25 -> 0.45238934
C26: 8 | E26: 3 | F26: =C26-E26-G26 -> 4 | G26: 1 | H26: TOP MIDD SHELL | I26: 1 | J26: =PI()*DIA*T.M.S.H*I26 -> 0.45238934 | K26: =PI()*DIA*T.M.S.H -> 0.45238934 | L26: =K26*E26*I26 -> 1.357168 | M26: =K26*F26*I26 -> 1.8095574 | N26: =K26*G26*I26 -> 0.45238934
C27: 8 | E27: 3 | F27: =C27-E27-G27 -> 4 | G27: 1 | H27: TOP SHELL | I27: 1 | J27: =PI()*DIA*T.S.H*I27 -> 0.45238934 | K27: =PI()*DIA*T.S.H -> 0.45238934 | L27: =K27*E27*I27 -> 1.357168 | M27: =K27*F27*I27 -> 1.8095574 | N27: =K27*G27*I27 -> 0.45238934
C28: 8 | E28: 0 | F28: 0 | G28: 0 | H28: CON TOP | I28: 1 | J28: =((DIA^2)/(COS(ANGLE*PI()/180)))*I28 -> 0.37269942 | K28: =PI()/4*((DIA^2)/(COS(ANGLE*PI()/180))) -> 0.29271744 | L28: =K28*E28*I28 -> 0 | M28: =K28*F28*I28 -> 0 | N28: =K28*G28*I28 -> 0
C29: 8 | E29: 3 | F29: =C29-E29-G29 -> 4 | G29: 1 | H29: FLAT BOTTM | I29: 1 | J29: =(DIA^2)*I29 -> 0.36 | K29: =(PI()/4)*(DIA^2) -> 0.28274334 | L29: =K29*E29*I29 -> 0.84823002 | M29: =K29*F29*I29 -> 1.1309734 | N29: =K29*G29*I29 -> 0.28274334
C30: 15 | E30: 3 | F30: =C30-E30-G30 -> 11 | G30: 1 | H30: BODY FLG | I30: 1 | J30: =((DIA+0.2)^2)*I30 -> 0.64 | K30: =((PI()/4)*((DIA+0.2)^2-DIA^2)) -> 0.21991149 | L30: =K30*E30*I30 -> 0.65973446 | M30: =K30*F30*I30 -> 2.4190263 | N30: =K30*G30*I30 -> 0.21991149
C31: 15 | E31: 3 | F31: =C31-E31-G31 -> 11 | G31: 1 | H31: TOP COVER | I31: 1 | J31: =((DIA+0.2)^2)*I31 -> 0.64 | K31: =((PI()/4)*((DIA+0.2)^2)) -> 0.50265482 | L31: =K31*E31*I31 -> 1.5079645 | M31: =K31*F31*I31 -> 5.5292031 | N31: =K31*G31*I31 -> 0.50265482
C32: =CEILING((C31+C23)*0.5,1) -> 12 | F32: =C32-E32-G32 -> 12 | H32: R/F - BOTTOM | I32: 1 | K32: =PI()*DIA*(2*2*SQRT(DIA*((C32)/1000/2))) -> 0.45238934 | M32: =K32*F32*I32 -> 5.4286721
C33: =CEILING((C31+C27)*0.5,1) -> 12 | F33: =C33-E33-G33 -> 12 | H33: R/F - TOP | I33: 1 | K33: =PI()*DIA*(2*2*SQRT(DIA*((C33)/1000/2))) -> 0.45238934 | M33: =K33*F33*I33 -> 5.4286721
C34: 0 | F34: =C34-E34-G34 -> 0 | H34: R/F -LUGS SUPPORT | I34: 1 | K34: =PI()*DIA*0.45 -> 0.84823002 | M34: =K34*F34*I34 -> 0
C35: 0 | F35: =C35-E35-G35 -> 0 | H35: STFFENER @TOP | I35: 0 | K35: =(DIA)/(COS(ANGLE*PI()/180))*((50+75+75+75+50)/1000) -> 0.20187886 | M35: =K35*F35*I35 -> 0
C36: 0 | F36: =C36-E36-G36 -> 0 | H36: SHEL STIFF | I36: 0 | K36: =PI()*DIA*0.4 -> 0.75398224 | M36: =K36*F36*I36 -> 0
V37: FLG. THICKNESS | X37: PIPE THICKNESS | Z37: FLG. AREA | AB37: PIPE AREA | AD37: TOTAL
Q38: NOZZLE | R38: PIPE SIZE | S38: PIPE LENGTH | T38: FLG. OD | U38: AREA | V38: PP | W38: FRP | X38: PP | Y38: FRP | Z38: PP | AA38: FRP | AB38: PP | AC38: FRP | AD38: PP (Sq.M) | AE38: FRP (Sq. M- mm)
P39: N001 | Q39: N001 | R39: 0 | S39: 0 | T39: 0 | U39: =((PI()/4)*(T39^2-R39^2))+(PI()*R39*S39) -> 0 | V39: 5 | W39: 12 | X39: 5 | Y39: 5 | Z39: =(T39^2)*CEILING(V39/4,1) -> 0 | AA39: =((PI()/4)*(T39^2-R39^2))*W39 -> 0 | AB39: =+(PI()*R39*S39)*CEILING(X39/3,1) -> 0 | AC39: =+(PI()*R39*S39)*Y39 -> 0 | AD39: =+Z39+AB39 -> 0 | AE39: =+AA39+AC39 -> 0
H40: N040 | I40: 4 | J40: =LOOKUP(H40,NOZZLE1,PP_AREA)*I40 -> 0.27982845 | L40: 1.39 | M40: =L40*I40 -> 5.56 | P40: N015 | Q40: N015 | R40: 0.015 | S40: 0.15 | T40: 0.089 | U40: =((PI()/4)*(T40^2-R40^2))+(PI()*R40*S40) -> 0.013113008 | V40: 5 | W40: 12 | X40: 5 | Y40: 5 | Z40: =(T40^2)*CEILING(V40/4,1) -> 0.015842 | AA40: =((PI()/4)*(T40^2-R40^2))*W40 -> 0.072533091 | AB40: =+(PI()*R40*S40)*CEILING(X40/3,1) -> 0.014137167 | AC40: =+(PI()*R40*S40)*Y40 -> 0.035342917 | AD40: =+Z40+AB40 -> 0.029979167 | AE40: =+AA40+AC40 -> 0.10787601
H41: N050 | I41: 2 | J41: =LOOKUP(H41,NOZZLE1,PP_AREA)*I41 -> 0.18666378 | L41: 1.7 | M41: =L41*I41 -> 3.4 | P41: N020 | Q41: N020 | R41: 0.02 | S41: 0.15 | T41: 0.098 | U41: =((PI()/4)*(T41^2-R41^2))+(PI()*R41*S41) -> 0.016653583 | V41: 5 | W41: 12 | X41: 5 | Y41: 5 | Z41: =(T41^2)*CEILING(V41/4,1) -> 0.019208 | AA41: =((PI()/4)*(T41^2-R41^2))*W41 -> 0.086745656 | AB41: =+(PI()*R41*S41)*CEILING(X41/3,1) -> 0.018849556 | AC41: =+(PI()*R41*S41)*Y41 -> 0.04712389 | AD41: =+Z41+AB41 -> 0.038057556 | AE41: =+AA41+AC41 -> 0.13386955
H42: N100 | I42: 2 | J42: =LOOKUP(H42,NOZZLE1,PP_AREA)*I42 -> 0.39825956 | L42: 1.9 | M42: =L42*I42 -> 3.8 | P42: N025 | Q42: N025 | R42: 0.025 | S42: 0.15 | T42: 0.108 | U42: =((PI()/4)*(T42^2-R42^2))+(PI()*R42*S42) -> 0.020450983 | V42: 5 | W42: 12 | X42: 5 | Y42: 5 | Z42: =(T42^2)*CEILING(V42/4,1) -> 0.023328 | AA42: =((PI()/4)*(T42^2-R42^2))*W42 -> 0.10404012 | AB42: =+(PI()*R42*S42)*CEILING(X42/3,1) -> 0.023561945 | AC42: =+(PI()*R42*S42)*Y42 -> 0.058904862 | AD42: =+Z42+AB42 -> 0.046889945 | AE42: =+AA42+AC42 -> 0.16294499
H43: N100 | I43: 0 | J43: =LOOKUP(H43,NOZZLE1,PP_AREA)*I43 -> 0 | L43: 1.55 | M43: =L43*I43 -> 0 | P43: N040 | Q43: N040 | R43: 0.04 | S43: 0.15 | T43: 0.127 | U43: =((PI()/4)*(T43^2-R43^2))+(PI()*R43*S43) -> 0.030260606 | V43: 5 | W43: 15 | X43: 5 | Y43: 6 | Z43: =(T43^2)*CEILING(V43/4,1) -> 0.032258 | AA43: =((PI()/4)*(T43^2-R43^2))*W43 -> 0.17116575 | AB43: =+(PI()*R43*S43)*CEILING(X43/3,1) -> 0.037699112 | AC43: =+(PI()*R43*S43)*Y43 -> 0.11309734 | AD43: =+Z43+AB43 -> 0.069957112 | AE43: =+AA43+AC43 -> 0.28426308
H44: N450 | I44: 0 | J44: =LOOKUP(H44,NOZZLE1,PP_AREA)*I44 -> 0 | L44: 7.34 | M44: =L44*I44 -> 0 | P44: N050 | Q44: N050 | R44: 0.05 | S44: 0.15 | T44: 0.152 | U44: =((PI()/4)*(T44^2-R44^2))+(PI()*R44*S44) -> 0.039744289 | V44: 5 | W44: 15 | X44: 5 | Y44: 6 | Z44: =(T44^2)*CEILING(V44/4,1) -> 0.046208 | AA44: =((PI()/4)*(T44^2-R44^2))*W44 -> 0.24273516 | AB44: =+(PI()*R44*S44)*CEILING(X44/3,1) -> 0.04712389 | AC44: =+(PI()*R44*S44)*Y44 -> 0.14137167 | AD44: =+Z44+AB44 -> 0.09333189 | AE44: =+AA44+AC44 -> 0.38410683
...

Sheet 05_0.942 KL
C1: DATE | D1: ='01_1.35 KL'!D1 -> 44551 | E1: R1
C2: DATE | D2: ='01_1.35 KL'!D2 -> 44530 | E2: R0 | M2: ='01_1.35 KL'!M2:M4 -> R1 | N2: 05
C3: TYPE | D3: VERTICAL CYLINDRICAL WITH FLAT TOP WITH COVER AND FLAT BOTTOM
C4: CLIENT | D4: M/s PARAMOUNT
C5: CAPACITY | D5: =M11 -> 0.9424778 | E5: KL
C6: TITLE | D6: ALKALI MEASURING TANK (SBA)
C10: DIAMETER | D10: =+J13/1000 -> 1 | F10: 21-T-007 A/B
C11: HEIGHT | D11: =+I13/1000 -> 1.2 | M11: =(PI()/4)*(DIA^2)*HT -> 0.9424778
C12: CONE ANGLE | D12: 15 | I12: HEIGHT | J12: DIAMETER
C13: B. SHELL HT. | D13: =+HT/5 -> 0.24 | I13: 1200 | J13: 1000
C14: B.M. SHELL HT. | D14: =+HT/5 -> 0.24 | I14: (in mm) | J14: (in mm)
C15: M. SHELL HT. | D15: =+HT/5 -> 0.24
C16: T.M. SHELL HT. | D16: =+HT/5 -> 0.24
C17: T. SHELL HT. | D17: =+HT/5 -> 0.24
C18: D.E.D | D18: =+DIA*1.2+0.1 -> 1.3
D20: M.O.C- FRP (BISPHENOL)
D21: THK | H21: PART | I21: Qty | J21: =D22 -> 0 | K21: FRP AREA | L21: =E22 -> BIS | M21: =F22 -> BIS | N21: =G22 -> BIS
C22: THK | E22: BIS | F22: BIS | G22: BIS | J22: Sq.M | K22: Sq.M | L22: Sq.M-mm | M22: Sq.M-mm | N22: Sq.M-mm
C23: 8 | E23: 3 | F23: =C23-E23-G23 -> 4 | G23: 1 | H23: BOTTOM SHELL | I23: 1 | J23: =PI()*DIA*D13*I23 -> 0.75398224 | K23: =PI()*DIA*D13 -> 0.75398224 | L23: =K23*E23*I23 -> 2.2619467 | M23: =K23*F23*I23 -> 3.0159289 | N23: =K23*G23*I23 -> 0.75398224
C24: 8 | E24: 3 | F24: =C24-E24-G24 -> 4 | G24: 1 | H24: BOTT MIDD SHELL | I24: 1 | J24: =PI()*DIA*B.M.S.H*I24 -> 0.75398224 | K24: =PI()*DIA*B.M.S.H -> 0.75398224 | L24: =K24*E24*I24 -> 2.2619467 | M24: =K24*F24*I24 -> 3.0159289 | N24: =K24*G24*I24 -> 0.75398224
C25: 8 | E25: 3 | F25: =C25-E25-G25 -> 4 | G25: 1 | H25: MIDDLE SHELL | I25: 1 | J25: =PI()*DIA*M.S.H*I25 -> 0.75398224 | K25: =PI()*DIA*M.S.H -> 0.75398224 | L25: =K25*E25*I25 -> 2.2619467 | M25: =K25*F25*I25 -> 3.0159289 | N25: =K25*G25*I25 -> 0.75398224
C26: 8 | E26: 3 | F26: =C26-E26-G26 -> 4 | G26: 1 | H26: TOP MIDD SHELL | I26: 1 | J26: =PI()*DIA*T.M.S.H*I26 -> 0.75398224 | K26: =PI()*DIA*T.M.S.H -> 0.75398224 | L26: =K26*E26*I26 -> 2.2619467 | M26: =K26*F26*I26 -> 3.0159289 | N26: =K26*G26*I26 -> 0.75398224
C27: 8 | E27: 3 | F27: =C27-E27-G27 -> 4 | G27: 1 | H27: TOP SHELL | I27: 1 | J27: =PI()*DIA*T.S.H*I27 -> 0.75398224 | K27: =PI()*DIA*T.S.H -> 0.75398224 | L27: =K27*E27*I27 -> 2.2619467 | M27: =K27*F27*I27 -> 3.0159289 | N27: =K27*G27*I27 -> 0.75398224
C28: 5 | E28: 0 | F28: 0 | G28: 0 | H28: CON TOP | I28: 1 | J28: =((DIA^2)/(COS(ANGLE*PI()/180)))*I28 -> 1.0352762 | K28: =PI()/4*((DIA^2)/(COS(ANGLE*PI()/180))) -> 0.81310401 | L28: =K28*E28*I28 -> 0 | M28: =K28*F28*I28 -> 0 | N28: =K28*G28*I28 -> 0
C29: 8 | E29: 3 | F29: =C29-E29-G29 -> 4 | G29: 1 | H29: FLAT BOTTM | I29: 1 | J29: =(DIA^2)*I29 -> 1 | K29: =(PI()/4)*(DIA^2) -> 0.78539816 | L29: =K29*E29*I29 -> 2.3561945 | M29: =K29*F29*I29 -> 3.1415927 | N29: =K29*G29*I29 -> 0.78539816
C30: 18 | E30: 3 | F30: =C30-E30-G30 -> 14 | G30: 1 | H30: BODY FLG | I30: 1 | J30: =((DIA+0.2)^2)*I30 -> 1.44 | K30: =((PI()/4)*((DIA+0.2)^2-DIA^2)) -> 0.34557519 | L30: =K30*E30*I30 -> 1.0367256 | M30: =K30*F30*I30 -> 4.8380527 | N30: =K30*G30*I30 -> 0.34557519
C31: 18 | E31: 3 | F31: =C31-E31-G31 -> 14 | G31: 1 | H31: TOP COVER | I31: 1 | J31: =((DIA+0.2)^2)*I31 -> 1.44 | K31: =((PI()/4)*((DIA+0.2)^2)) -> 1.1309734 | L31: =K31*E31*I31 -> 3.3929201 | M31: =K31*F31*I31 -> 15.833627 | N31: =K31*G31*I31 -> 1.1309734
C32: =CEILING((C31+C23)*0.5,1) -> 13 | F32: =C32-E32-G32 -> 13 | H32: R/F - BOTTOM | I32: 1 | K32: =PI()*DIA*(2*2*SQRT(DIA*((C32)/1000/2))) -> 1.0131332 | M32: =K32*F32*I32 -> 13.170731
C33: =CEILING((C31+C27)*0.5,1) -> 13 | F33: =C33-E33-G33 -> 13 | H33: R/F - TOP | I33: 1 | K33: =PI()*DIA*(2*2*SQRT(DIA*((C33)/1000/2))) -> 1.0131332 | M33: =K33*F33*I33 -> 13.170731
C34: 0 | F34: =C34-E34-G34 -> 0 | H34: R/F -LUGS SUPPORT | I34: 1 | K34: =PI()*DIA*0.45 -> 1.4137167 | M34: =K34*F34*I34 -> 0
C35: 0 | F35: =C35-E35-G35 -> 0 | H35: STFFENER @TOP | I35: 0 | K35: =(DIA)/(COS(ANGLE*PI()/180))*((50+75+75+75+50)/1000) -> 0.33646476 | M35: =K35*F35*I35 -> 0
C36: 0 | F36: =C36-E36-G36 -> 0 | H36: SHEL STIFF | I36: 0 | K36: =PI()*DIA*0.4 -> 1.2566371 | M36: =K36*F36*I36 -> 0
V37: FLG. THICKNESS | X37: PIPE THICKNESS | Z37: FLG. AREA | AB37: PIPE AREA | AD37: TOTAL
Q38: NOZZLE | R38: PIPE SIZE | S38: PIPE LENGTH | T38: FLG. OD | U38: AREA | V38: PP | W38: FRP | X38: PP | Y38: FRP | Z38: PP | AA38: FRP | AB38: PP | AC38: FRP | AD38: PP (Sq.M) | AE38: FRP (Sq. M- mm)
P39: N001 | Q39: N001 | R39: 0 | S39: 0 | T39: 0 | U39: =((PI()/4)*(T39^2-R39^2))+(PI()*R39*S39) -> 0 | V39: 5 | W39: 12 | X39: 5 | Y39: 5 | Z39: =(T39^2)*CEILING(V39/4,1) -> 0 | AA39: =((PI()/4)*(T39^2-R39^2))*W39 -> 0 | AB39: =+(PI()*R39*S39)*CEILING(X39/3,1) -> 0 | AC39: =+(PI()*R39*S39)*Y39 -> 0 | AD39: =+Z39+AB39 -> 0 | AE39: =+AA39+AC39 -> 0
H40: N040 | I40: 4 | J40: =LOOKUP(H40,NOZZLE1,PP_AREA)*I40 -> 0.27982845 | L40: 1.39 | M40: =L40*I40 -> 5.56 | P40: N015 | Q40: N015 | R40: 0.015 | S40: 0.15 | T40: 0.089 | U40: =((PI()/4)*(T40^2-R40^2))+(PI()*R40*S40) -> 0.013113008 | V40: 5 | W40: 12 | X40: 5 | Y40: 5 | Z40: =(T40^2)*CEILING(V40/4,1) -> 0.015842 | AA40: =((PI()/4)*(T40^2-R40^2))*W40 -> 0.072533091 | AB40: =+(PI()*R40*S40)*CEILING(X40/3,1) -> 0.014137167 | AC40: =+(PI()*R40*S40)*Y40 -> 0.035342917 | AD40: =+Z40+AB40 -> 0.029979167 | AE40: =+AA40+AC40 -> 0.10787601
H41: N050 | I41: 2 | J41: =LOOKUP(H41,NOZZLE1,PP_AREA)*I41 -> 0.18666378 | L41: 1.7 | M41: =L41*I41 -> 3.4 | P41: N020 | Q41: N020 | R41: 0.02 | S41: 0.15 | T41: 0.098 | U41: =((PI()/4)*(T41^2-R41^2))+(PI()*R41*S41) -> 0.016653583 | V41: 5 | W41: 12 | X41: 5 | Y41: 5 | Z41: =(T41^2)*CEILING(V41/4,1) -> 0.019208 | AA41: =((PI()/4)*(T41^2-R41^2))*W41 -> 0.086745656 | AB41: =+(PI()*R41*S41)*CEILING(X41/3,1) -> 0.018849556 | AC41: =+(PI()*R41*S41)*Y41 -> 0.04712389 | AD41: =+Z41+AB41 -> 0.038057556 | AE41: =+AA41+AC41 -> 0.13386955
H42: N100 | I42: 3 | J42: =LOOKUP(H42,NOZZLE1,PP_AREA)*I42 -> 0.59738934 | L42: 1.9 | M42: =L42*I42 -> 5.7 | P42: N025 | Q42: N025 | R42: 0.025 | S42: 0.15 | T42: 0.108 | U42: =((PI()/4)*(T42^2-R42^2))+(PI()*R42*S42) -> 0.020450983 | V42: 5 | W42: 12 | X42: 5 | Y42: 5 | Z42: =(T42^2)*CEILING(V42/4,1) -> 0.023328 | AA42: =((PI()/4)*(T42^2-R42^2))*W42 -> 0.10404012 | AB42: =+(PI()*R42*S42)*CEILING(X42/3,1) -> 0.023561945 | AC42: =+(PI()*R42*S42)*Y42 -> 0.058904862 | AD42: =+Z42+AB42 -> 0.046889945 | AE42: =+AA42+AC42 -> 0.16294499
H43: N100 | I43: 0 | J43: =LOOKUP(H43,NOZZLE1,PP_AREA)*I43 -> 0 | L43: 1.55 | M43: =L43*I43 -> 0 | P43: N040 | Q43: N040 | R43: 0.04 | S43: 0.15 | T43: 0.127 | U43: =((PI()/4)*(T43^2-R43^2))+(PI()*R43*S43) -> 0.030260606 | V43: 5 | W43: 15 | X43: 5 | Y43: 6 | Z43: =(T43^2)*CEILING(V43/4,1) -> 0.032258 | AA43: =((PI()/4)*(T43^2-R43^2))*W43 -> 0.17116575 | AB43: =+(PI()*R43*S43)*CEILING(X43/3,1) -> 0.037699112 | AC43: =+(PI()*R43*S43)*Y43 -> 0.11309734 | AD43: =+Z43+AB43 -> 0.069957112 | AE43: =+AA43+AC43 -> 0.28426308
H44: N450 | I44: 0 | J44: =LOOKUP(H44,NOZZLE1,PP_AREA)*I44 -> 0 | L44: 7.34 | M44: =L44*I44 -> 0 | P44: N050 | Q44: N050 | R44: 0.05 | S44: 0.15 | T44: 0.152 | U44: =((PI()/4)*(T44^2-R44^2))+(PI()*R44*S44) -> 0.039744289 | V44: 5 | W44: 15 | X44: 5 | Y44: 6 | Z44: =(T44^2)*CEILING(V44/4,1) -> 0.046208 | AA44: =((PI()/4)*(T44^2-R44^2))*W44 -> 0.24273516 | AB44: =+(PI()*R44*S44)*CEILING(X44/3,1) -> 0.04712389 | AC44: =+(PI()*R44*S44)*Y44 -> 0.14137167 | AD44: =+Z44+AB44 -> 0.09333189 | AE44: =+AA44+AC44 -> 0.38410683
...

Sheet 06_0.330 KL
C1: DATE | D1: ='01_1.35 KL'!D1 -> 44551 | E1: R1
C2: DATE | D2: ='01_1.35 KL'!D2 -> 44530 | E2: R0 | M2: ='01_1.35 KL'!M2:M4 -> R1 | N2: 03 & 06
C3: TYPE | D3: VERTICAL CYLINDRICAL WITH FLAT TOP WITH COVER AND FLAT BOTTOM
C4: CLIENT | D4: M/s PARAMOUNT
C5: CAPACITY | D5: =M11 -> 0.33929201 | E5: KL
C6: TITLE | D6: ACID MEASURING TANK (MB)
C10: DIAMETER | D10: =+J13/1000 -> 0.6 | F10: 21-T-006 A/B
C11: HEIGHT | D11: =+I13/1000 -> 1.2 | M11: =(PI()/4)*(DIA^2)*HT -> 0.33929201
C12: CONE ANGLE | D12: 15 | I12: HEIGHT | J12: DIAMETER
C13: B. SHELL HT. | D13: =+HT/5 -> 0.24 | I13: 1200 | J13: 600
C14: B.M. SHELL HT. | D14: =+HT/5 -> 0.24 | I14: (in mm) | J14: (in mm)
C15: M. SHELL HT. | D15: =+HT/5 -> 0.24
C16: T.M. SHELL HT. | D16: =+HT/5 -> 0.24
C17: T. SHELL HT. | D17: =+HT/5 -> 0.24
C18: D.E.D | D18: =+DIA*1.2+0.1 -> 0.82
D20: M.O.C- FRP (BISPHENOL)
D21: THK | H21: PART | I21: Qty | J21: =D22 -> 0 | K21: FRP AREA | L21: =E22 -> BIS | M21: =F22 -> BIS | N21: =G22 -> BIS
C22: THK | E22: BIS | F22: BIS | G22: BIS | J22: Sq.M | K22: Sq.M | L22: Sq.M-mm | M22: Sq.M-mm | N22: Sq.M-mm
C23: 8 | E23: 3 | F23: =C23-E23-G23 -> 4 | G23: 1 | H23: BOTTOM SHELL | I23: 1 | J23: =PI()*DIA*D13*I23 -> 0.45238934 | K23: =PI()*DIA*D13 -> 0.45238934 | L23: =K23*E23*I23 -> 1.357168 | M23: =K23*F23*I23 -> 1.8095574 | N23: =K23*G23*I23 -> 0.45238934
C24: 8 | E24: 3 | F24: =C24-E24-G24 -> 4 | G24: 1 | H24: BOTT MIDD SHELL | I24: 1 | J24: =PI()*DIA*B.M.S.H*I24 -> 0.45238934 | K24: =PI()*DIA*B.M.S.H -> 0.45238934 | L24: =K24*E24*I24 -> 1.357168 | M24: =K24*F24*I24 -> 1.8095574 | N24: =K24*G24*I24 -> 0.45238934
C25: 8 | E25: 3 | F25: =C25-E25-G25 -> 4 | G25: 1 | H25: MIDDLE SHELL | I25: 1 | J25: =PI()*DIA*M.S.H*I25 -> 0.45238934 | K25: =PI()*DIA*M.S.H -> 0.45238934 | L25: =K25*E25*I25 -> 1.357168 | M25: =K25*F25*I25 -> 1.8095574 | N25: =K25*G25*I25 -> 0.45238934
C26: 8 | E26: 3 | F26: =C26-E26-G26 -> 4 | G26: 1 | H26: TOP MIDD SHELL | I26: 1 | J26: =PI()*DIA*T.M.S.H*I26 -> 0.45238934 | K26: =PI()*DIA*T.M.S.H -> 0.45238934 | L26: =K26*E26*I26 -> 1.357168 | M26: =K26*F26*I26 -> 1.8095574 | N26: =K26*G26*I26 -> 0.45238934
C27: 8 | E27: 3 | F27: =C27-E27-G27 -> 4 | G27: 1 | H27: TOP SHELL | I27: 1 | J27: =PI()*DIA*T.S.H*I27 -> 0.45238934 | K27: =PI()*DIA*T.S.H -> 0.45238934 | L27: =K27*E27*I27 -> 1.357168 | M27: =K27*F27*I27 -> 1.8095574 | N27: =K27*G27*I27 -> 0.45238934
C28: 8 | E28: 0 | F28: 0 | G28: 0 | H28: CON TOP | I28: 1 | J28: =((DIA^2)/(COS(ANGLE*PI()/180)))*I28 -> 0.37269942 | K28: =PI()/4*((DIA^2)/(COS(ANGLE*PI()/180))) -> 0.29271744 | L28: =K28*E28*I28 -> 0 | M28: =K28*F28*I28 -> 0 | N28: =K28*G28*I28 -> 0
C29: 8 | E29: 3 | F29: =C29-E29-G29 -> 4 | G29: 1 | H29: FLAT BOTTM | I29: 1 | J29: =(DIA^2)*I29 -> 0.36 | K29: =(PI()/4)*(DIA^2) -> 0.28274334 | L29: =K29*E29*I29 -> 0.84823002 | M29: =K29*F29*I29 -> 1.1309734 | N29: =K29*G29*I29 -> 0.28274334
C30: 15 | E30: 3 | F30: =C30-E30-G30 -> 11 | G30: 1 | H30: BODY FLG | I30: 1 | J30: =((DIA+0.2)^2)*I30 -> 0.64 | K30: =((PI()/4)*((DIA+0.2)^2-DIA^2)) -> 0.21991149 | L30: =K30*E30*I30 -> 0.65973446 | M30: =K30*F30*I30 -> 2.4190263 | N30: =K30*G30*I30 -> 0.21991149
C31: 15 | E31: 3 | F31: =C31-E31-G31 -> 11 | G31: 1 | H31: TOP COVER | I31: 1 | J31: =((DIA+0.2)^2)*I31 -> 0.64 | K31: =((PI()/4)*((DIA+0.2)^2)) -> 0.50265482 | L31: =K31*E31*I31 -> 1.5079645 | M31: =K31*F31*I31 -> 5.5292031 | N31: =K31*G31*I31 -> 0.50265482
C32: =CEILING((C31+C23)*0.5,1) -> 12 | F32: =C32-E32-G32 -> 12 | H32: R/F - BOTTOM | I32: 1 | K32: =PI()*DIA*(2*2*SQRT(DIA*((C32)/1000/2))) -> 0.45238934 | M32: =K32*F32*I32 -> 5.4286721
C33: =CEILING((C31+C27)*0.5,1) -> 12 | F33: =C33-E33-G33 -> 12 | H33: R/F - TOP | I33: 1 | K33: =PI()*DIA*(2*2*SQRT(DIA*((C33)/1000/2))) -> 0.45238934 | M33: =K33*F33*I33 -> 5.4286721
C34: 0 | F34: =C34-E34-G34 -> 0 | H34: R/F -LUGS SUPPORT | I34: 1 | K34: =PI()*DIA*0.45 -> 0.84823002 | M34: =K34*F34*I34 -> 0
C35: 0 | F35: =C35-E35-G35 -> 0 | H35: STFFENER @TOP | I35: 0 | K35: =(DIA)/(COS(ANGLE*PI()/180))*((50+75+75+75+50)/1000) -> 0.20187886 | M35: =K35*F35*I35 -> 0
C36: 0 | F36: =C36-E36-G36 -> 0 | H36: SHEL STIFF | I36: 0 | K36: =PI()*DIA*0.4 -> 0.75398224 | M36: =K36*F36*I36 -> 0
V37: FLG. THICKNESS | X37: PIPE THICKNESS | Z37: FLG. AREA | AB37: PIPE AREA | AD37: TOTAL
Q38: NOZZLE | R38: PIPE SIZE | S38: PIPE LENGTH | T38: FLG. OD | U38: AREA | V38: PP | W38: FRP | X38: PP | Y38: FRP | Z38: PP | AA38: FRP | AB38: PP | AC38: FRP | AD38: PP (Sq.M) | AE38: FRP (Sq. M- mm)
P39: N001 | Q39: N001 | R39: 0 | S39: 0 | T39: 0 | U39: =((PI()/4)*(T39^2-R39^2))+(PI()*R39*S39) -> 0 | V39: 5 | W39: 12 | X39: 5 | Y39: 5 | Z39: =(T39^2)*CEILING(V39/4,1) -> 0 | AA39: =((PI()/4)*(T39^2-R39^2))*W39 -> 0 | AB39: =+(PI()*R39*S39)*CEILING(X39/3,1) -> 0 | AC39: =+(PI()*R39*S39)*Y39 -> 0 | AD39: =+Z39+AB39 -> 0 | AE39: =+AA39+AC39 -> 0
H40: N040 | I40: 4 | J40: =LOOKUP(H40,NOZZLE1,PP_AREA)*I40 -> 0.27982845 | L40: 1.39 | M40: =L40*I40 -> 5.56 | P40: N015 | Q40: N015 | R40: 0.015 | S40: 0.15 | T40: 0.089 | U40: =((PI()/4)*(T40^2-R40^2))+(PI()*R40*S40) -> 0.013113008 | V40: 5 | W40: 12 | X40: 5 | Y40: 5 | Z40: =(T40^2)*CEILING(V40/4,1) -> 0.015842 | AA40: =((PI()/4)*(T40^2-R40^2))*W40 -> 0.072533091 | AB40: =+(PI()*R40*S40)*CEILING(X40/3,1) -> 0.014137167 | AC40: =+(PI()*R40*S40)*Y40 -> 0.035342917 | AD40: =+Z40+AB40 -> 0.029979167 | AE40: =+AA40+AC40 -> 0.10787601
H41: N050 | I41: 2 | J41: =LOOKUP(H41,NOZZLE1,PP_AREA)*I41 -> 0.18666378 | L41: 1.7 | M41: =L41*I41 -> 3.4 | P41: N020 | Q41: N020 | R41: 0.02 | S41: 0.15 | T41: 0.098 | U41: =((PI()/4)*(T41^2-R41^2))+(PI()*R41*S41) -> 0.016653583 | V41: 5 | W41: 12 | X41: 5 | Y41: 5 | Z41: =(T41^2)*CEILING(V41/4,1) -> 0.019208 | AA41: =((PI()/4)*(T41^2-R41^2))*W41 -> 0.086745656 | AB41: =+(PI()*R41*S41)*CEILING(X41/3,1) -> 0.018849556 | AC41: =+(PI()*R41*S41)*Y41 -> 0.04712389 | AD41: =+Z41+AB41 -> 0.038057556 | AE41: =+AA41+AC41 -> 0.13386955
H42: N150 | I42: 3 | J42: =LOOKUP(H42,NOZZLE1,PP_AREA)*I42 -> 0.89116101 | L42: 2.71 | M42: =L42*I42 -> 8.13 | P42: N025 | Q42: N025 | R42: 0.025 | S42: 0.15 | T42: 0.108 | U42: =((PI()/4)*(T42^2-R42^2))+(PI()*R42*S42) -> 0.020450983 | V42: 5 | W42: 12 | X42: 5 | Y42: 5 | Z42: =(T42^2)*CEILING(V42/4,1) -> 0.023328 | AA42: =((PI()/4)*(T42^2-R42^2))*W42 -> 0.10404012 | AB42: =+(PI()*R42*S42)*CEILING(X42/3,1) -> 0.023561945 | AC42: =+(PI()*R42*S42)*Y42 -> 0.058904862 | AD42: =+Z42+AB42 -> 0.046889945 | AE42: =+AA42+AC42 -> 0.16294499
H43: N100 | I43: 0 | J43: =LOOKUP(H43,NOZZLE1,PP_AREA)*I43 -> 0 | L43: 1.55 | M43: =L43*I43 -> 0 | P43: N040 | Q43: N040 | R43: 0.04 | S43: 0.15 | T43: 0.127 | U43: =((PI()/4)*(T43^2-R43^2))+(PI()*R43*S43) -> 0.030260606 | V43: 5 | W43: 15 | X43: 5 | Y43: 6 | Z43: =(T43^2)*CEILING(V43/4,1) -> 0.032258 | AA43: =((PI()/4)*(T43^2-R43^2))*W43 -> 0.17116575 | AB43: =+(PI()*R43*S43)*CEILING(X43/3,1) -> 0.037699112 | AC43: =+(PI()*R43*S43)*Y43 -> 0.11309734 | AD43: =+Z43+AB43 -> 0.069957112 | AE43: =+AA43+AC43 -> 0.28426308
H44: N450 | I44: 0 | J44: =LOOKUP(H44,NOZZLE1,PP_AREA)*I44 -> 0 | L44: 7.34 | M44: =L44*I44 -> 0 | P44: N050 | Q44: N050 | R44: 0.05 | S44: 0.15 | T44: 0.152 | U44: =((PI()/4)*(T44^2-R44^2))+(PI()*R44*S44) -> 0.039744289 | V44: 5 | W44: 15 | X44: 5 | Y44: 6 | Z44: =(T44^2)*CEILING(V44/4,1) -> 0.046208 | AA44: =((PI()/4)*(T44^2-R44^2))*W44 -> 0.24273516 | AB44: =+(PI()*R44*S44)*CEILING(X44/3,1) -> 0.04712389 | AC44: =+(PI()*R44*S44)*Y44 -> 0.14137167 | AD44: =+Z44+AB44 -> 0.09333189 | AE44: =+AA44+AC44 -> 0.38410683
...

Sheet RESIN RATE
E1: 44512
A2: HAND LAY UP | N2: 05
B3: ISOPHTHALIC | C3: DERAKANE 470.300 | D3: BIS | E3: 3 mm PP
A4: RESIN MAKE | B4: CREST -CPOL 331 | C4: ASHLAND | D4: FRP
A6: 1 KG RESIN | B6: 145 | C6: 550 | D6: 325 | E6: 0
A7: 0.5 KG GLASS | B7: 78 | C7: 78 | D7: 98
A8: CONSU+ HARD + PIG | B8: 20 | C8: 20 | D8: 20
A9: 5 % OF RM | B9: =+(B6+B7)*5/100 -> 11.15 | C9: =+(C6+C7)*5/100 -> 31.4 | D9: =+(D6+D7)*5/100 -> 21.15
A10: LABOUR | B10: 100 | C10: 100 | D10: 100 | E10: 0
B11: =SUM(B6:B10) -> 354.15 | C11: =SUM(C6:C10) -> 779.4 | D11: =SUM(D6:D10) -> 564.15 | E11: =SUM(E6:E10) -> 0
A12: RATE PER M2 mm | B12: =CEILING(B11,5) -> 355 | C12: =CEILING(C11,5) -> 780 | D12: =CEILING(D11,5) -> 565 | E12: =CEILING(E11,5) -> 0

Sheet THK
A2: SUMMARY_THICKNESS
J3: DATE : 30.11.2021
A4: SR. NO. | B4: IITEM | C4: CAP. | D4: SIZE | E4: QTY | F4: MOC | G4: THK BY CLIENT | H4: THK BY MINIMUM WALL THK (MALLINSON) | I4: THK BY BS 4994 | J4: ACTUAL THK CONSIDERD
A5: 1 | B5: ACID MEASURING TANK (SAC) | C5: 1.35 KL | D5: 1200 ID X 1200 LG. | E5: 2 | F5: 3 mm PP + FRP (VINYL) | G5: NOT GIVEN VENDOR TO CONFIRM | H5: 3 mm CB + 5 mm FRP | I5: 3 mm CB + 5 mm FRP | J5: SHELL : FLAT : FLG & COVER :
A6: 2 | B6: FUME ABSORBER (SAC) | C6: 0.021 KL | D6: 300 ID X 300 LG. | E6: 1 | F6: FRP (VINYL) | G6: NOT GIVEN VENDOR TO CONFIRM | H6: 3 mm CB + 5 mm FRP | I6: 3 mm CB + 5 mm FRP | J6: SHELL : FLAT : FLG & COVER :
A7: 3 | B7: ACID MEASURING TANK (MB) | C7: 0.330 KL | D7: 600 ID X 1200 LG. | E7: 1 | F7: 3 mm PP + FRP (VINYL) | G7: NOT GIVEN VENDOR TO CONFIRM | H7: 3 mm CB + 5 mm FRP | I7: 3 mm CB + 5 mm FRP | J7: SHELL : FLAT : FLG & COVER :
A8: 4 | B8: FUME ABSORBER (MB) | C8: 0.021 KL | D8: 300 ID X 300 LG. | E8: 1 | F8: FRP (VINYL) | G8: NOT GIVEN VENDOR TO CONFIRM | H8: 3 mm CB + 5 mm FRP | I8: 3 mm CB + 5 mm FRP | J8: SHELL : FLAT : FLG & COVER :
A9: 5 | B9: ALKALI MEASURING TANK (SBA) | C9: 0.942 KL | D9: 1000 ID X 1200 LG. | E9: 2 | F9: 3 mm PP + FRP (VINYL) | G9: NOT GIVEN VENDOR TO CONFIRM | H9: 3 mm CB + 5 mm FRP | I9: 3 mm CB + 5 mm FRP | J9: SHELL : FLAT : FLG & COVER :
A10: 6 | B10: ALKALI MEASURING / DILUTION TANK (MB) | C10: 0.340 KL | D10: 600 ID X 1200 LG. | E10: 1 | F10: 3 mm PP + FRP (VINYL) | G10: NOT GIVEN VENDOR TO CONFIRM | H10: 3 mm CB + 5 mm FRP | I10: 3 mm CB + 5 mm FRP | J10: SHELL : FLAT : FLG & COVER :
